Workbook
Name MC_Bore_Area: [1]GeomAndTestNotes!$B$3

Sheet ReadMe
A1: constant input
A2: feel adjustment parameter
A6: feel adjustment parameters | B6: brake | C6: torque - pressure curve
B8: BMV | C8: transfer spring rate
C9: transfer spring deadband
C10: input bore diameter
B12: pedal mechnism | C12: master cylinder moment arms (upper and lower)
B14: master cylinder | C14: feel spring rate
C15: feel spring deadband/ precompression
C16: bore diameter
C17: master cylinder deadband

Sheet Brake capability
A1: This tab plots the capability of the brakes
A3: fraction over | B3: 0.15 | C3: -
A5: Hydraulic Brake Pressure | B5: Brake Torque | C5: Brake torque uncertatinty, under | D5: Brake torque uncertatinty, over
A6: psi | B6: ft-Lbf | C6: ft-Lbf | D6: ft-Lbf
A7: 110 | B7: 0 | C7: =B7*(1-B$3) -> 0 | D7: =B7*(1+B$3) -> 0
A8: 208 | B8: 1431 | C8: =B8*(1-B$3) -> 1216.35 | D8: =B8*(1+B$3) -> 1645.65
A9: 435 | B9: 2731 | C9: =B9*(1-B$3) -> 2321.35 | D9: =B9*(1+B$3) -> 3140.65
A10: 661 | B10: 3800 | C10: =B10*(1-B$3) -> 3230 | D10: =B10*(1+B$3) -> 4370
A11: 889 | B11: 4663 | C11: =B11*(1-B$3) -> 3963.55 | D11: =B11*(1+B$3) -> 5362.45
A12: 1118 | B12: 5369 | C12: =B12*(1-B$3) -> 4563.65 | D12: =B12*(1+B$3) -> 6174.35
A13: 1346 | B13: 5993 | C13: =B13*(1-B$3) -> 5094.05 | D13: =B13*(1+B$3) -> 6891.95
A14: 1573 | B14: 6567 | C14: =B14*(1-B$3) -> 5581.95 | D14: =B14*(1+B$3) -> 7552.05
A15: 1805 | B15: 7134 | C15: =B15*(1-B$3) -> 6063.9 | D15: =B15*(1+B$3) -> 8204.1
A16: 2035 | B16: 7741 | C16: =B16*(1-B$3) -> 6579.85 | D16: =B16*(1+B$3) -> 8902.15

Sheet pedal model
A1: This tab illustrates models pedal geometry in realation to BMV volume input
A3: mc length unstroked | B3: 11.5 | C3: in
A4: max mc stroke | B4: 1.4 | C4: in
A5: bmv vol input | B5: 0.11 | C5: in^3
A6: hose vol deadband | B6: 0.003 | C6: in^3 | D6: set by results from data review 2
A7: MC stroke deadband | B7: 0.085 | C7: in | D7: .085" unshimmed, .05" is starting place for shimming
B9: x | C9: y
A10: pedal axis | B10: 0 | C10: 0
A11: rudder axis | B11: 0 | C11: 11
A14: mc top to pedal axis | B14: =SQRT((B20^2)+(C20^2)) -> 11.18034
A15: mc arm | B15: 2
A16: angle 1 | B16: =ATAN(B20/C20) -> 0.1798535
A17: angle 2 | B17: =ACOS(((-(B3^2))+(B14^2)+(B15^2))/(2*B15*B14)) -> 1.6435327
A18: angle 3 | B18: =B17+B16 -> 1.8233862
A19: angle 4 | B19: =B18-(PI()/2) -> 0.25258983
A20: MC top | B20: 2 | C20: 11 | J20: in model
F21: bore diameter | G21: =5/8 -> 0.625 | H21: =9/16 -> 0.5625 | I21: 0.5 | J21: =I21 -> 0.5 | K21: in
F22: bore area | G22: =PI()*(G21/2)^2 -> 0.30679616 | H22: =PI()*(H21/2)^2 -> 0.24850489 | I22: =PI()*(I21/2)^2 -> 0.19634954 | J22: =I22 -> 0.19634954 | K22: in^2
F23: stroke deadband | G23: =G22*$B7 -> 0.026077673 | H23: =H22*$B7 -> 0.021122915 | I23: =I22*$B7 -> 0.016689711 | J23: =I23 -> 0.016689711 | K23: in^3
F24: input deadband | G24: =G23+$B6 -> 0.029077673 | H24: =H23+$B6 -> 0.024122915 | I24: =I23+$B6 -> 0.019689711 | J24: =I24 -> 0.019689711 | K24: in^3
C26: arm/MC connection
A27: pedal angle | B27: pedal angle | C27: x | D27: y | E27: MC length | F27: MC stroke | G27: vol displace | K27: MC/MC Arm Angle | L27: angle | M27: percent force realized | N27: mc vol limit | O27: MC stroke limit
A28: deg | B28: rad | C28: in | D28: in | F28: in | G28: in^3 | H28: in^3 | I28: in^3 | J28: =I28 -> in^3 | K28: rad | L28: deg | M28: % | N28: in^3 | O28: angle
A29: 0 | B29: {=[2]!deg2rad(A29)} -> 0 | C29: =COS(B$18-(PI()/2)-B29)*B$15 -> 1.9365369 | D29: =-SIN(B$18-(PI()/2)-B29)*B$15 -> -0.49982489 | E29: =SQRT(ABS(C29-B$20)^2+ABS(D29-C$20)^2) -> 11.5 | F29: =$B$3-SQRT(ABS(C29-B$20)^2+ABS(D29-C$20)^2) -> 0 | G29: =($F29*G$22)-G$23-$B$6 -> -0.029077673 | H29: =($F29*H$22)-H$23-$B$6 -> -0.024122915 | I29: =($F29*I$22)-I$23-$B$6 -> -0.019689711 | J29: =H29 -> -0.024122915 | K29: =ACOS((-(B$14^2)+B$15^2+E29^2)/(2*E29*B$15)) -> 1.3237251 | L29: 75.843859 | M29: =COS(K29-(PI()/2)) -> 0.96963285 | N29: =B$5 -> 0.11 | O29: =[2]!linear_intp_2col(F$29:F$38,A$29:A$38,B$4) -> 41.314928
A30: =A29+5 -> 5 | B30: {=[2]!deg2rad(A30)} -> 0.087266463 | C30: =COS(B$18-(PI()/2)-B30)*B$15 -> 1.9727304 | D30: =-SIN(B$18-(PI()/2)-B30)*B$15 -> -0.32914259 | E30: =SQRT(ABS(C30-B$20)^2+ABS(D30-C$20)^2) -> 11.329175 | F30: =$B$3-SQRT(ABS(C30-B$20)^2+ABS(D30-C$20)^2) -> 0.17082459 | G30: =($F30*G$22)-G$23-$B$6 -> 0.023330654 | H30: =($F30*H$22)-H$23-$B$6 -> 0.01832783 | I30: =($F30*I$22)-I$23-$B$6 -> 0.013851618 | J30: =H30 -> 0.01832783 | K30: =ACOS((-(B$14^2)+B$15^2+E30^2)/(2*E30*B$15)) -> 1.40788 | L30: 80.665581 | M30: =COS(K30-(PI()/2)) -> 0.98675846 | N30: =B$5 -> 0.11 | O30: =[2]!linear_intp_2col(F$29:F$38,A$29:A$38,B$4) -> 41.314928
A31: =A30+5 -> 10 | B31: {=[2]!deg2rad(A31)} -> 0.17453293 | C31: =COS(B$18-(PI()/2)-B31)*B$15 -> 1.9939102 | D31: =-SIN(B$18-(PI()/2)-B31)*B$15 -> -0.15595532 | E31: =SQRT(ABS(C31-B$20)^2+ABS(D31-C$20)^2) -> 11.155957 | F31: =$B$3-SQRT(ABS(C31-B$20)^2+ABS(D31-C$20)^2) -> 0.34404301 | G31: =($F31*G$22)-G$23-$B$6 -> 0.076473401 | H31: =($F31*H$22)-H$23-$B$6 -> 0.061373455 | I31: =($F31*I$22)-I$23-$B$6 -> 0.047862977 | J31: =H31 -> 0.061373455 | K31: =ACOS((-(B$14^2)+B$15^2+E31^2)/(2*E31*B$15)) -> 1.4932853 | L31: 85.558945 | M31: =COS(K31-(PI()/2)) -> 0.99699752 | N31: =B$5 -> 0.11 | O31: =[2]!linear_intp_2col(F$29:F$38,A$29:A$38,B$4) -> 41.314928
A32: =A31+5 -> 15 | B32: {=[2]!deg2rad(A32)} -> 0.26179939 | C32: =COS(B$18-(PI()/2)-B32)*B$15 -> 1.9999152 | D32: =-SIN(B$18-(PI()/2)-B32)*B$15 -> 0.018418859 | E32: =SQRT(ABS(C32-B$20)^2+ABS(D32-C$20)^2) -> 10.981581 | F32: =$B$3-SQRT(ABS(C32-B$20)^2+ABS(D32-C$20)^2) -> 0.51841886 | G32: =($F32*G$22)-G$23-$B$6 -> 0.12997124 | H32: =($F32*H$22)-H$23-$B$6 -> 0.1047067 | I32: =($F32*I$22)-I$23-$B$6 -> 0.082101594 | J32: =H32 -> 0.1047067 | K32: =ACOS((-(B$14^2)+B$15^2+E32^2)/(2*E32*B$15)) -> 1.5800136 | L32: 90.528111 | M32: =COS(K32-(PI()/2)) -> 0.99995752 | N32: =B$5 -> 0.11 | O32: =[2]!linear_intp_2col(F$29:F$38,A$29:A$38,B$4) -> 41.314928
A33: =A32+5 -> 20 | B33: {=[2]!deg2rad(A33)} -> 0.34906585 | C33: =COS(B$18-(PI()/2)-B33)*B$15 -> 1.9906996 | D33: =-SIN(B$18-(PI()/2)-B33)*B$15 -> 0.19265286 | E33: =SQRT(ABS(C33-B$20)^2+ABS(D33-C$20)^2) -> 10.807351 | F33: =$B$3-SQRT(ABS(C33-B$20)^2+ABS(D33-C$20)^2) -> 0.69264886 | G33: =($F33*G$22)-G$23-$B$6 -> 0.18342434 | H33: =($F33*H$22)-H$23-$B$6 -> 0.14800371 | I33: =($F33*I$22)-I$23-$B$6 -> 0.11631157 | J33: =H33 -> 0.14800371 | K33: =ACOS((-(B$14^2)+B$15^2+E33^2)/(2*E33*B$15)) -> 1.6681329 | L33: 95.576976 | M33: =COS(K33-(PI()/2)) -> 0.99526653 | N33: =B$5 -> 0.11 | O33: =[2]!linear_intp_2col(F$29:F$38,A$29:A$38,B$4) -> 41.314928
A34: =A33+5 -> 25 | B34: {=[2]!deg2rad(A34)} -> 0.43633231 | C34: =COS(B$18-(PI()/2)-B34)*B$15 -> 1.9663336 | D34: =-SIN(B$18-(PI()/2)-B34)*B$15 -> 0.36542066 | E34: =SQRT(ABS(C34-B$20)^2+ABS(D34-C$20)^2) -> 10.634633 | F34: =$B$3-SQRT(ABS(C34-B$20)^2+ABS(D34-C$20)^2) -> 0.86536737 | G34: =($F34*G$22)-G$23-$B$6 -> 0.23641371 | H34: =($F34*H$22)-H$23-$B$6 -> 0.19092511 | I34: =($F34*I$22)-I$23-$B$6 -> 0.15022478 | J34: =H34 -> 0.19092511 | K34: =ACOS((-(B$14^2)+B$15^2+E34^2)/(2*E34*B$15)) -> 1.7577046 | L34: 100.70905 | M34: =COS(K34-(PI()/2)) -> 0.98258345 | N34: =B$5 -> 0.11 | O34: =[2]!linear_intp_2col(F$29:F$38,A$29:A$38,B$4) -> 41.314928
A35: =A34+5 -> 30 | B35: {=[2]!deg2rad(A35)} -> 0.52359878 | C35: =COS(B$18-(PI()/2)-B35)*B$15 -> 1.9270026 | D35: =-SIN(B$18-(PI()/2)-B35)*B$15 -> 0.53540739 | E35: =SQRT(ABS(C35-B$20)^2+ABS(D35-C$20)^2) -> 10.464847 | F35: =$B$3-SQRT(ABS(C35-B$20)^2+ABS(D35-C$20)^2) -> 1.0351528 | G35: =($F35*G$22)-G$23-$B$6 -> 0.28850323 | H35: =($F35*H$22)-H$23-$B$6 -> 0.23311761 | I35: =($F35*I$22)-I$23-$B$6 -> 0.18356206 | J35: =H35 -> 0.23311761 | K35: =ACOS((-(B$14^2)+B$15^2+E35^2)/(2*E35*B$15)) -> 1.8487808 | L35: 105.92734 | M35: =COS(K35-(PI()/2)) -> 0.96161048 | N35: =B$5 -> 0.11 | O35: =[2]!linear_intp_2col(F$29:F$38,A$29:A$38,B$4) -> 41.314928
A36: =A35+5 -> 35 | B36: {=[2]!deg2rad(A36)} -> 0.61086524 | C36: =COS(B$18-(PI()/2)-B36)*B$15 -> 1.8730059 | D36: =-SIN(B$18-(PI()/2)-B36)*B$15 -> 0.70131934 | E36: =SQRT(ABS(C36-B$20)^2+ABS(D36-C$20)^2) -> 10.299464 | F36: =$B$3-SQRT(ABS(C36-B$20)^2+ABS(D36-C$20)^2) -> 1.2005364 | G36: =($F36*G$22)-G$23-$B$6 -> 0.33924228 | H36: =($F36*H$22)-H$23-$B$6 -> 0.27421624 | I36: =($F36*I$22)-I$23-$B$6 -> 0.21603506 | J36: =H36 -> 0.27421624 | K36: =ACOS((-(B$14^2)+B$15^2+E36^2)/(2*E36*B$15)) -> 1.9414022 | L36: 111.23415 | M36: =COS(K36-(PI()/2)) -> 0.93210808 | N36: =B$5 -> 0.11 | O36: =[2]!linear_intp_2col(F$29:F$38,A$29:A$38,B$4) -> 41.314928
A37: =A36+5 -> 40 | B37: {=[2]!deg2rad(A37)} -> 0.6981317 | C37: =COS(B$18-(PI()/2)-B37)*B$15 -> 1.8047546 | D37: =-SIN(B$18-(PI()/2)-B37)*B$15 -> 0.86189383 | E37: =SQRT(ABS(C37-B$20)^2+ABS(D37-C$20)^2) -> 10.139986 | F37: =$B$3-SQRT(ABS(C37-B$20)^2+ABS(D37-C$20)^2) -> 1.3600139 | G37: =($F37*G$22)-G$23-$B$6 -> 0.38816938 | H37: =($F37*H$22)-H$23-$B$6 -> 0.31384719 | I37: =($F37*I$22)-I$23-$B$6 -> 0.2473484 | J37: =H37 -> 0.31384719 | K37: =ACOS((-(B$14^2)+B$15^2+E37^2)/(2*E37*B$15)) -> 2.0355944 | L37: 116.63097 | M37: =COS(K37-(PI()/2)) -> 0.8939121 | N37: =B$5 -> 0.11 | O37: =[2]!linear_intp_2col(F$29:F$38,A$29:A$38,B$4) -> 41.314928
A38: =A37+5 -> 45 | B38: {=[2]!deg2rad(A38)} -> 0.78539816 | C38: =COS(B$18-(PI()/2)-B38)*B$15 -> 1.7227679 | D38: =-SIN(B$18-(PI()/2)-B38)*B$15 -> 1.0159088 | E38: =SQRT(ABS(C38-B$20)^2+ABS(D38-C$20)^2) -> 9.9879395 | F38: =$B$3-SQRT(ABS(C38-B$20)^2+ABS(D38-C$20)^2) -> 1.5120605 | G38: =($F38*G$22)-G$23-$B$6 -> 0.43481669 | H38: =($F38*H$22)-H$23-$B$6 -> 0.35163152 | I38: =($F38*I$22)-I$23-$B$6 -> 0.27720268 | J38: =H38 -> 0.35163152 | K38: =ACOS((-(B$14^2)+B$15^2+E38^2)/(2*E38*B$15)) -> 2.1313649 | L38: 117.63097 | M38: =COS(K38-(PI()/2)) -> 0.84695295 | N38: =B$5 -> 0.11 | O38: =[2]!linear_intp_2col(F$29:F$38,A$29:A$38,B$4) -> 41.314928

Sheet Brake feel deisgn space
A1: This tab interprets the brake feel requirements
A3: design point 1 | B3: pedal force | C3: 65 | D3: lbf | E3: slide 12
B4: aircraft decel | C4: 0.22 | D4: G's | E4: slide 12
A6: design point 2 | B6: pedal force | C6: 100 | D6: lbf | E6: slide 12
B7: pedal angle | C7: 20 | D7: degrees | E7: slide 12
B8: aircraft decel | C8: 0.4 | D8: G's | E8: slide 12
A10: mil spec guidance | B10: max max travel limit | C10: 25 | D10: degrees | E10: MIL-B-8584 pg6
B11: min max travel limit | C11: 15 | D11: degrees | E11: MIL-B-8584 pg6
B12: max force for initial brake pedal movement | C12: 20 | D12: lbf | E12: MIL-B-8584
B13: min force for initial brake pedal movement | C13: 15 | D13: lbf | E13: MIL-B-8584
B14: max max braking force | C14: 125 | D14: lbf | E14: MIL-B-8584
B15: min max braking force | C15: 75 | D15: lbf | E15: MIL-B-8584
B16: initial angle | C16: 0 | D16: degrees
B17: initial angle 2 | C17: 5 | D17: degrees

Sheet engine run install
C1: calc value | E1: notes
A2: bmv geom | B2: BMV max stroke | C2: 0.56 | D2: in
B3: BMV max delta vol | C3: =C2*C11 -> 0.10995574 | D3: in^3
B4: despin max stroke | C4: 0.155 | D4: in
B5: despin diameter in | C5: 0.5 | D5: in
B6: despin area in | C6: =PI()*(C5/2)^2 -> 0.19634954 | D6: in^2
B7: despin max delta vol | C7: =C6*C4 -> 0.030434179 | D7: in^3
B8: despin diameter out | C8: 0.55 | D8: in
B9: despin area out | C9: =PI()*(C8/2)^2 -> 0.23758294 | D9: in^2
B10: D_input_1 | C10: 0.5 | D10: in
B11: A_input_1 | C11: =((C10/2)^2)*PI() -> 0.19634954 | D11: in^2
B12: D_input_2 | C12: 0.5 | D12: in | E12: no effect if no return pressure
B13: A_input_2 | C13: =((C12/2)^2)*PI() -> 0.19634954 | D13: in^2
B14: D_spool | C14: 0.26 | D14: in | E14: no effect if no return pressure
B15: A_spool | C15: =((C14/2)^2)*PI() -> 0.053092916 | D15: in^2
B16: D_output | C16: 0.19 | D16: in
B17: A_output | C17: =((C16/2)^2)*PI() -> 0.028352874 | D17: in^2
A18: springs | B18: output spring uncompressed length | C18: 0.7 | D18: in | E18: measurment
B19: output sping K | C19: 9 | D19: lbf/in | E19: measurment
B20: output spring loaded length | C20: 0.525 | D20: in | E20: .45" min, .6 max, .525" mid
B21: F output spring compress | C21: =(C18-C20)*C19 -> 1.575 | D21: lbf
B22: output spring loaded length | C22: =C20+0.06 -> 0.585 | D22: in
B23: F output spring extend | C23: =(C18-C22)*C19 -> 1.035 | D23: lbf
B24: L_0 input spring | C24: 1.75 | D24: in
B25: L_0 deadband | C25: 0.03 | D25: in
B26: L_install input spring | C26: =C25+C24 -> 1.78 | D26: in
A27: other constants | B27: return pressure | C27: 50 | D27: psi
B28: F friction | C28: 0 | D28: lbf | E28: used for distinction between extend and compress
A29: Brake pedal feel | B29: MC bore diameter | C29: ='pedal model'!J21 -> 0.5 | D29: in
B30: MC bore area | C30: ='pedal model'!J22 -> 0.19634954 | D30: in^2
B31: MC length | C31: ='pedal model'!B3 -> 11.5 | D31: in
B32: MC lever arm | C32: ='pedal model'!B15 -> 2 | D32: in
B33: pedal force application lever arm | C33: 5 | D33: in
A34: Aircraft feel | B34: wheel center to ground | C34: 10.9 | D34: in
B35: wheel center to ground | C35: =C34/12 -> 0.90833333 | D35: ft
B36: F_prop | C36: 500 | D36: lbf
B37: std air density | C37: 0.002377 | D37: slug/ft^3
B38: air density | C38: 0.002048 | D38: slugs/ft^3
B39: C_d*Area Zero Alpha Gear Down | C39: 9.25 | D39: ft^2
B40: initial braking | C40: 110 | D40: psi
...

Sheet master cylinder spring
B1: cots | C1: custom | D1: installed
A2: starting force | B2: 6 | C2: =C7*C5 -> 12.138529 | D2: =B2 -> 6 | E2: lbf
A3: final force | B3: 23 | D3: =B3 -> 23 | E3: lbf
A4: stroke | B4: 1.4 | D4: =B4 -> 1.4 | E4: in
A5: k | B5: =(B3-B2)/B4 -> 12.142857 | C5: 30 | D5: =B5 -> 12.142857 | E5: lbf/in
A6: length | B6: 3.5895 | C6: 3.5 | D6: =B6 -> 3.5895 | E6: in
A7: calculated precompression | B7: =B2/B5 -> 0.49411765 | C7: =C6-$B11 -> 0.40461765 | D7: =B7 -> 0.49411765 | E7: in
A8: min total stroke | B8: =B7+B4 -> 1.8941176 | D8: =B8 -> 1.8941176 | E8: in
A9: OD | B9: 0.44 | D9: =B9 -> 0.44
A10: ID | B10: 0.34 | D10: =B10 -> 0.34
A11: initial length | B11: =B6-B7 -> 3.0953824 | D11: =B11 -> 3.0953824
A12: final length | B12: =B11-B4 -> 1.6953824 | D12: =B12 -> 1.6953824

Sheet 429 brake feel test
W1: 1700, 0 keas | Y1: 1300, 0 keas
C2: tooch | E2: Duff | G2: Doc | K2: tooch | N2: Duff | P2: Doc | R2: Doc/duff avg
B3: force | C3: LH | D3: RH | E3: LH | F3: RH | G3: LH | H3: RH | K3: LH | L3: RH | N3: LH | O3: RH | P3: LH | Q3: RH | R3: LH | S3: RH | T3: diff | W3: LH | X3: RH | Y3: LH | Z3: RH
A4: low | B4: 1 | C4: 110 | D4: 27 | E4: 115 | F4: 58 | G4: 120 | H4: 58 | J4: 1 | K4: =AVERAGE(C4:C6) -> 110 | L4: =AVERAGE(D4:D6) -> 27 | N4: =AVERAGE(E4:E6) -> 167.5 | O4: =AVERAGE(F4:F6) -> 77.5 | P4: =AVERAGE(G4:G6) -> 155 | Q4: =AVERAGE(H4:H6) -> 59.333333 | R4: =AVERAGE(N4,P4) -> 161.25 | S4: =AVERAGE(O4,Q4) -> 68.416667 | T4: =S4-R4 -> -92.833333 | W4: =[2]!linear_intp_2col('engine run install'!$I$65:$I$77,'engine run install'!$AA$65:$AA$77,R4) -> 0.060176015 | X4: =[2]!linear_intp_2col('engine run install'!$I$65:$I$77,'engine run install'!$AA$65:$AA$77,S4) -> -0.045264508 | Y4: =[2]!linear_intp_2col('engine run install'!$I$65:$I$77,'engine run install'!$AJ$65:$AJ$77,R4) -> 0.083569479 | Z4: =[2]!linear_intp_2col('engine run install'!$I$65:$I$77,'engine run install'!$AJ$65:$AJ$77,S4) -> -0.054314282
A5: low | B5: 1 | E5: 220 | F5: 97 | G5: 175 | H5: 60 | J5: 2 | K5: =AVERAGE(C7:C9) -> 244 | L5: =AVERAGE(D7:D9) -> 70 | N5: =AVERAGE(E7:E9) -> 325 | O5: =AVERAGE(F7:F9) -> 213 | P5: =AVERAGE(G7:G9) -> 320 | Q5: =AVERAGE(H7:H9) -> 204 | R5: =AVERAGE(N5,P5) -> 322.5 | S5: =AVERAGE(O5,Q5) -> 208.5 | T5: =S5-R5 -> -114 | W5: =[2]!linear_intp_2col('engine run install'!$I$65:$I$77,'engine run install'!$AA$65:$AA$77,R5) -> 0.22500773 | X5: =[2]!linear_intp_2col('engine run install'!$I$65:$I$77,'engine run install'!$AA$65:$AA$77,S5) -> 0.11758475 | Y5: =[2]!linear_intp_2col('engine run install'!$I$65:$I$77,'engine run install'!$AJ$65:$AJ$77,R5) -> 0.29911864 | Z5: =[2]!linear_intp_2col('engine run install'!$I$65:$I$77,'engine run install'!$AJ$65:$AJ$77,S5) -> 0.15864244
A6: low | B6: 1 | G6: 170 | H6: 60 | J6: 3 | K6: =AVERAGE(C10:C12) -> 397.5 | L6: =AVERAGE(D10:D12) -> 185.5 | N6: =AVERAGE(E10:E12) -> 504 | O6: =AVERAGE(F10:F12) -> 436 | P6: =AVERAGE(G10:G12) -> 480.33333 | Q6: =AVERAGE(H10:H12) -> 360 | R6: =AVERAGE(N6,P6) -> 492.16667 | S6: =AVERAGE(O6,Q6) -> 398 | T6: =S6-R6 -> -94.166667 | W6: =[2]!linear_intp_2col('engine run install'!$I$65:$I$77,'engine run install'!$AA$65:$AA$77,R6) -> 0.34347635 | X6: =[2]!linear_intp_2col('engine run install'!$I$65:$I$77,'engine run install'!$AA$65:$AA$77,S6) -> 0.27998729 | Y6: =[2]!linear_intp_2col('engine run install'!$I$65:$I$77,'engine run install'!$AJ$65:$AJ$77,R6) -> 0.45403915 | Z6: =[2]!linear_intp_2col('engine run install'!$I$65:$I$77,'engine run install'!$AJ$65:$AJ$77,S6) -> 0.37101499
A7: med | B7: 2 | C7: 223 | D7: 36 | E7: 322 | F7: 206 | G7: 250 | H7: 162 | J7: 4 | K7: =AVERAGE(C13:C15) -> 610 | L7: =AVERAGE(D13:D15) -> 385 | N7: =AVERAGE(E13:E15) -> 730 | O7: =AVERAGE(F13:F15) -> 610.5 | P7: =AVERAGE(G13:G15) -> 645 | Q7: =AVERAGE(H13:H15) -> 513.5 | R7: =AVERAGE(N7,P7) -> 687.5 | S7: =AVERAGE(O7,Q7) -> 562 | T7: =S7-R7 -> -125.5 | W7: =[2]!linear_intp_2col('engine run install'!$I$65:$I$77,'engine run install'!$AA$65:$AA$77,R7) -> 0.45870785 | X7: =[2]!linear_intp_2col('engine run install'!$I$65:$I$77,'engine run install'!$AA$65:$AA$77,S7) -> 0.38625902 | Y7: =[2]!linear_intp_2col('engine run install'!$I$65:$I$77,'engine run install'!$AJ$65:$AJ$77,R7) -> 0.60472649 | Z7: =[2]!linear_intp_2col('engine run install'!$I$65:$I$77,'engine run install'!$AJ$65:$AJ$77,S7) -> 0.50998572
A8: med | B8: 2 | C8: 265 | D8: 104 | E8: 328 | F8: 220 | G8: 360 | H8: 220
A9: med | B9: 2 | G9: 350 | H9: 230 | T9: {=avg} -> #NAME?
A10: high | B10: 3 | C10: 359 | D10: 130 | E10: 502 | F10: 422 | G10: 480 | H10: 360
A11: high | B11: 3 | C11: 436 | D11: 241 | E11: 506 | F11: 450 | G11: 481 | H11: 360
A12: high | B12: 3 | G12: 480 | H12: 360
A13: max | B13: 4 | C13: 620 | D13: 420 | E13: 730 | F13: 591 | G13: 640 | H13: 515
A14: max | B14: 4 | C14: 600 | D14: 350 | F14: 630 | G14: 650 | H14: 512
A15: max | B15: 4
A20: test notes
A21: no boots
A22: parachute on
A23: dc pump power for doc and duff
A24: mule power for tooch
A25: beginning light force not an issue!
A26: duff push rods
A27: right seat position?
